Workbook

Sheet LEIA-ME
A1: PROJEÇÃO DOS CONCURSOS DE ARQUITETURA — OUT/2026 A DEZ/2028
A3: O que é: um modelo trimestral (9 trimestres) com três cenários, do ritmo atual de concursos até o fim de 2028.
A4: Como usar: as células AMARELAS são suposições. Mude a aba Premissas (e as linhas de inscrições nas abas de cenário) e tudo recalcula.
A6: O que NÃO é dado medido:
A7: • Chances, prêmios médios, honorários, margens, impostos, divisão com a JOJO e a renda da perna 2 são estimativas minhas.
A8: • A renda da perna 2 é um chute total (R$ 6–8 mil/mês). É a premissa que mais mexe na renda total — coloque a sua.
A9: • Os prêmios e prazos dos editais (UFC 21/10, Maringá 11/11) vêm do que li antes; confira nos editais.
A10: • A UFC e o Maringá estão tratados como concursos nacionais genéricos. A UFC tem contrato muito maior; o modelo a subestima.
A11: • A planilha anterior (24 meses) não estava neste ambiente; reconstruí as premissas a partir das conversas. Os números podem diferir um pouco dela.
A13: Como o modelo funciona:
A14: • Resultado de cada concurso sai um trimestre depois da inscrição.
A15: • Um contrato ganho começa a pagar 3 trimestres depois do resultado e paga em 4 parcelas trimestrais iguais.
... A20: Abas: Premissas · Conservador · Realista · Otimista · Resumo · Monte Carlo · Marcos

Sheet Resumo
A1: RESUMO — OUT/2026 A DEZ/2028
A2: Valores esperados (média). Veja a aba Monte Carlo para a dispersão. Suposições amarelas na aba Premissas.
A4: Total do período | B4: Conservador | C4: Realista | D4: Otimista
A5: Concursos inscritos (nacionais + internacionais) | B5: ='Conservador'!L7+'Conservador'!L8 | C5: ='Realista'!L7+'Realista'!L8 | D5: ='Otimista'!L7+'Otimista'!L8
A6: Horas em concursos | B6: ='Conservador'!L20 | C6: ='Realista'!L20 | D6: ='Otimista'!L20
A7: Prêmios esperados (bruto) | B7: ='Conservador'!L25 | C7: ='Realista'!L25 | D7: ='Otimista'!L25
A8: Contratos esperados ganhos (nº) | B8: ='Conservador'!L14 | C8: ='Realista'!L14 | D8: ='Otimista'!L14
A9: Contratos recebidos até dez/2028 (sua parte, bruto de imposto) | B9: ='Conservador'!L26 | C9: ='Realista'!L26 | D9: ='Otimista'!L26
A10: Caixa líquido dos concursos | B10: ='Conservador'!L31 | C10: ='Realista'!L31 | D10: ='Otimista'!L31
A11: Líquido depois do valor das horas | B11: ='Conservador'!L33 | C11: ='Realista'!L33 | D11: ='Otimista'!L33
A12: Perna 2 (PSCIP/Revit/casa) | B12: ='Conservador'!L35 | C12: ='Realista'!L35 | D12: ='Otimista'!L35
A13: RENDA TOTAL no período | B13: ='Conservador'!L36 | C13: ='Realista'!L36 | D13: ='Otimista'!L36
A14: Renda mensal média no período | B14: ='Conservador'!L37 | C14: ='Realista'!L37 | D14: ='Otimista'!L37
A15: Carteira de contratos ganhos a receber DEPOIS de 2028 (líquido) | B15: ='Conservador'!L42 | C15: ='Realista'!L42 | D15: ='Otimista'!L42
A18: Por ano — Conservador
B19: 2026 (só T4) | C19: 2027 | D19: 2028
A20: Prêmios (bruto) | B20: =SUM('Conservador'!C25:C25) | C20: =SUM('Conservador'!D25:G25) | D20: =SUM('Conservador'!H25:K25)
A21: Contratos (sua parte) | B21: =SUM('Conservador'!C26:C26) | C21: =SUM('Conservador'!D26:G26) | D21: =SUM('Conservador'!H26:K26)
A22: Caixa líquido dos concursos | B22: =SUM('Conservador'!C31:C31) | C22: =SUM('Conservador'!D31:G31) | D22: =SUM('Conservador'!H31:K31)
A23: Perna 2 | B23: =SUM('Conservador'!C35:C35) | C23: =SUM('Conservador'!D35:G35) | D23: =SUM('Conservador'!H35:K35)
A24: Renda total | B24: =SUM('Conservador'!C36:C36) | C24: =SUM('Conservador'!D36:G36) | D24: =SUM('Conservador'!H36:K36)
A25: Horas totais | B25: =SUM('Conservador'!C21:C21) | C25: =SUM('Conservador'!D21:G21) | D25: =SUM('Conservador'!H21:K21)
A26: Renda mensal média | B26: =B24/3 | C26: =C24/12 | D26: =D24/12
A29: Por ano — Realista
B30: 2026 (só T4) | C30: 2027 | D30: 2028
A31: Prêmios (bruto) | B31: =SUM('Realista'!C25:C25) | C31: =SUM('Realista'!D25:G25) | D31: =SUM('Realista'!H25:K25)
A32: Contratos (sua parte) | B32: =SUM('Realista'!C26:C26) | C32: =SUM('Realista'!D26:G26) | D32: =SUM('Realista'!H26:K26)
A33: Caixa líquido dos concursos | B33: =SUM('Realista'!C31:C31) | C33: =SUM('Realista'!D31:G31) | D33: =SUM('Realista'!H31:K31)
A34: Perna 2 | B34: =SUM('Realista'!C35:C35) | C34: =SUM('Realista'!D35:G35) | D34: =SUM('Realista'!H35:K35)
A35: Renda total | B35: =SUM('Realista'!C36:C36) | C35: =SUM('Realista'!D36:G36) | D35: =SUM('Realista'!H36:K36)
A36: Horas totais | B36: =SUM('Realista'!C21:C21) | C36: =SUM('Realista'!D21:G21) | D36: =SUM('Realista'!H21:K21)
A37: Renda mensal média | B37: =B35/3 | C37: =C35/12 | D37: =D35/12
A40: Por ano — Otimista
B41: 2026 (só T4) | C41: 2027 | D41: 2028
A42: Prêmios (bruto) | B42: =SUM('Otimista'!C25:C25) | C42: =SUM('Otimista'!D25:G25) | D42: =SUM('Otimista'!H25:K25)
A43: Contratos (sua parte) | B43: =SUM('Otimista'!C26:C26) | C43: =SUM('Otimista'!D26:G26) | D43: =SUM('Otimista'!H26:K26)
A44: Caixa líquido dos concursos | B44: =SUM('Otimista'!C31:C31) | C44: =SUM('Otimista'!D31:G31) | D44: =SUM('Otimista'!H31:K31)
A45: Perna 2 | B45: =SUM('Otimista'!C35:C35) | C45: =SUM('Otimista'!D35:G35) | D45: =SUM('Otimista'!H35:K35)
A46: Renda total | B46: =SUM('Otimista'!C36:C36) | C46: =SUM('Otimista'!D36:G36) | D46: =SUM('Otimista'!H36:K36)
A47: Horas totais | B47: =SUM('Otimista'!C21:C21) | C47: =SUM('Otimista'!D21:G21) | D47: =SUM('Otimista'!H21:K21)
...

Sheet Premissas
A1: PREMISSAS (células amarelas = você troca)
A2: Tudo aqui é estimativa minha, não dado medido, salvo onde o edital for citado.
A4: Parâmetro | B4: Unid. | C4: Conservador | D4: Realista | E4: Otimista | F4: Observação
A5: Câmbio EUR→BRL | B5: R$/€ | C5: 6.2 | D5: 6.2 | E5: 6.2 | F5: Chute. Prêmios internacionais convertidos por ele.
A6: Chance de 1º lugar por inscrição nacional | B6: % | C6: 0.02 | D6: 0.035 | E6: 0.05 | F6: Estimativa minha: 2–5% no nacional aberto (extremos e meio da faixa).
A7: Chance de menção/2º–3º por inscrição nacional | B7: % | C7: 0.12 | D7: 0.18 | E7: 0.24 | F7: Estimativa minha (somada ao 1º dá 15–25% de 'premiado').
A8: Chance de 1º lugar por inscrição internacional | B8: % | C8: 0.005 | D8: 0.01 | E8: 0.015 | F8: Estimativa minha: ~1% no internacional.
A9: Chance de menção/colocação por inscrição internacional | B9: % | C9: 0.06 | D9: 0.1 | E9: 0.14 | F9: Estimativa minha.
A10: Prêmio médio do 1º lugar nacional | B10: R$ | C10: 40000 | D10: 60000 | E10: 80000 | F10: Chute. Confira nos editais; a UFC não teve os prêmios menores levantados.
A11: Prêmio médio de menção/colocação nacional | B11: R$ | C11: 8000 | D11: 8000 | E11: 8000 | F11: Chute.
A12: Prêmio médio do 1º lugar internacional | B12: € | C12: 10000 | D12: 10000 | E12: 10000 | F12: Chute.
A13: Prêmio médio de menção internacional | B13: € | C13: 1500 | D13: 1500 | E13: 1500 | F13: Chute.
A14: Chance de virar contrato quando ganha 1º nacional | B14: % | C14: 0.4 | D14: 0.6 | E14: 0.75 | F14: Depende de CNPJ e acervo CAT-A. Sem eles, cai muito.
A15: Honorário bruto de um contrato típico | B15: R$ | C15: 250000 | D15: 350000 | E15: 600000 | F15: Faixa que dei antes: R$ 150–500 mil. A UFC (obra de R$ 7,24 mi) pode ser maior.
A16: Margem sobre o honorário (depois de equipe/terceiros) | B16: % | C16: 0.55 | D16: 0.55 | E16: 0.55 | F16: Chute.
... A32: Trimestre (nº) em que a alta começa (1=T4/26 … 9=T4/28) | B32: nº | C32: 99 | D32: 4 | E32: 3 | F32: 99 = nunca acontece.

Sheet Conservador
A1: CENÁRIO CONSERVADOR — valor esperado por trimestre
A2: Amarelo = inscrições por trimestre (você escolhe). O resto é fórmula ligada à aba Premissas.
A4: Item | B4: Unid. | C4: T4/26 | D4: T1/27 | E4: T2/27 | F4: T3/27 | G4: T4/27 | H4: T1/28 | I4: T2/28 | J4: T3/28 | K4: T4/28 | L4: Total
A5: Nº do trimestre | C5: 1 | D5: 2 | E5: 3 | F5: 4 | G5: 5 | H5: 6 | I5: 7 | J5: 8 | K5: 9
A6: ENTRADAS
A7: Concursos nacionais grandes inscritos | B7: nº | C7: 2 | D7: 0 | E7: 1 | F7: 0 | G7: 1 | H7: 0 | I7: 1 | J7: 0 | K7: 1 | L7: =SUM(C7:K7)
A8: Concursos internacionais inscritos | B8: nº | C8: 0 | D8: 1 | E8: 1 | F8: 1 | G8: 1 | H8: 0 | I8: 1 | J8: 1 | K8: 0 | L8: =SUM(C8:K8)
A9: RESULTADOS (saem 1 trimestre após a inscrição)
A10: Resultados nacionais | B10: nº | C10: 0 | D10: =C7 | E10: =D7 | F10: =E7 | G10: =F7 | H10: =G7 | I10: =H7 | J10: =I7 | K10: =J7 | L10: =SUM(C10:K10)
A11: Resultados internacionais | B11: nº | C11: 0 | D11: =C8 | E11: =D8 | F11: =E8 | G11: =F8 | H11: =G8 | I11: =H8 | J11: =I8 | K11: =J8 | L11: =SUM(C11:K11)
A12: Prêmios esperados — nacionais | B12: R$ | C12: =C10*(Premissas!$C$6*Premissas!$C$10+Premissas!$C$7*Premissas!$C$11) | D12: =D10*(Premissas!$C$6*Premissas!$C$10+Premissas!$C$7*Premissas!$C$11) | E12: =E10*(Premissas!$C$6*Premissas!$C$10+Premissas!$C$7*Premissas!$C$11) | F12: =F10*(Premissas!$C$6*Premissas!$C$10+Premissas!$C$7*Premissas!$C$11) | G12: =G10*(Premissas!$C$6*Premissas!$C$10+Premissas!$C$7*Premissas!$C$11) | H12: =H10*(Premissas!$C$6*Premissas!$C$10+Premissas!$C$7*Premissas!$C$11) | I12: =I10*(Premissas!$C$6*Premissas!$C$10+Premissas!$C$7*Premissas!$C$11) | J12: =J10*(Premissas!$C$6*Premissas!$C$10+Premissas!$C$7*Premissas!$C$11) | K12: =K10*(Premissas!$C$6*Premissas!$C$10+Premissas!$C$7*Premissas!$C$11) | L12: =SUM(C12:K12)
A13: Prêmios esperados — internacionais | B13: R$ | C13: =C11*(Premissas!$C$8*Premissas!$C$12+Premissas!$C$9*Premissas!$C$13)*Premissas!$C$5 | D13: =D11*(Premissas!$C$8*Premissas!$C$12+Premissas!$C$9*Premissas!$C$13)*Premissas!$C$5 | E13: =E11*(Premissas!$C$8*Premissas!$C$12+Premissas!$C$9*Premissas!$C$13)*Premissas!$C$5 | F13: =F11*(Premissas!$C$8*Premissas!$C$12+Premissas!$C$9*Premissas!$C$13)*Premissas!$C$5 | G13: =G11*(Premissas!$C$8*Premissas!$C$12+Premissas!$C$9*Premissas!$C$13)*Premissas!$C$5 | H13: =H11*(Premissas!$C$8*Premissas!$C$12+Premissas!$C$9*Premissas!$C$13)*Premissas!$C$5 | I13: =I11*(Premissas!$C$8*Premissas!$C$12+Premissas!$C$9*Premissas!$C$13)*Premissas!$C$5 | J13: =J11*(Premissas!$C$8*Premissas!$C$12+Premissas!$C$9*Premissas!$C$13)*Premissas!$C$5 | K13: =K11*(Premissas!$C$8*Premissas!$C$12+Premissas!$C$9*Premissas!$C$13)*Premissas!$C$5 | L13: =SUM(C13:K13)
A14: Contratos esperados ganhos (nº) | B14: nº | C14: =C10*Premissas!$C$6*Premissas!$C$14 | D14: =D10*Premissas!$C$6*Premissas!$C$14 | E14: =E10*Premissas!$C$6*Premissas!$C$14 | F14: =F10*Premissas!$C$6*Premissas!$C$14 | G14: =G10*Premissas!$C$6*Premissas!$C$14 | H14: =H10*Premissas!$C$6*Premissas!$C$14 | I14: =I10*Premissas!$C$6*Premissas!$C$14 | J14: =J10*Premissas!$C$6*Premissas!$C$14 | K14: =K10*Premissas!$C$6*Premissas!$C$14 | L14: =SUM(C14:K14)
A15: CONTRATOS (pagam 3 trimestres após o resultado, em 4 parcelas)
A16: Honorário bruto recebido pelo escritório | B16: R$ | C16: =Premissas!$C$15/4*0 | D16: =Premissas!$C$15/4*0 | E16: =Premissas!$C$15/4*0 | F16: =Premissas!$C$15/4*SUM(C14:C14) | G16: =Premissas!$C$15/4*SUM(C14:D14) | H16: =Premissas!$C$15/4*SUM(C14:E14) | I16: =Premissas!$C$15/4*SUM(C14:F14) | J16: =Premissas!$C$15/4*SUM(D14:G14) | K16: =Premissas!$C$15/4*SUM(E14:H14) | L16: =SUM(C16:K16)
A17: Sua parte, antes do imposto (margem × divisão) | B17: R$ | C17: =C16*Premissas!$C$16*Premissas!$C$17 | D17: =D16*Premissas!$C$16*Premissas!$C$17 | E17: =E16*Premissas!$C$16*Premissas!$C$17 | F17: =F16*Premissas!$C$16*Premissas!$C$17 | G17: =G16*Premissas!$C$16*Premissas!$C$17 | H17: =H16*Premissas!$C$16*Premissas!$C$17 | I17: =I16*Premissas!$C$16*Premissas!$C$17 | J17: =J16*Premissas!$C$16*Premissas!$C$17 | K17: =K16*Premissas!$C$16*Premissas!$C$17 | L17: =SUM(C17:K17)
A18: Horas de execução dos contratos | B18: h | C18: =Premissas!$C$22/4*0 | D18: =Premissas!$C$22/4*0 | E18: =Premissas!$C$22/4*0 | F18: =Premissas!$C$22/4*SUM(C14:C14) | G18: =Premissas!$C$22/4*SUM(C14:D14) | H18: =Premissas!$C$22/4*SUM(C14:E14) | I18: =Premissas!$C$22/4*SUM(C14:F14) | J18: =Premissas!$C$22/4*SUM(D14:G14) | K18: =Premissas!$C$22/4*SUM(E14:H14) | L18: =SUM(C18:K18)
A19: HORAS
A20: Horas de concurso | B20: h | C20: =C7*Premissas!$C$20+C8*Premissas!$C$21 | D20: =D7*Premissas!$C$20+D8*Premissas!$C$21 | E20: =E7*Premissas!$C$20+E8*Premissas!$C$21 | F20: =F7*Premissas!$C$20+F8*Premissas!$C$21 | G20: =G7*Premissas!$C$20+G8*Premissas!$C$21 | H20: =H7*Premissas!$C$20+H8*Premissas!$C$21 | I20: =I7*Premissas!$C$20+I8*Premissas!$C$21 | J20: =J7*Premissas!$C$20+J8*Premissas!$C$21 | K20: =K7*Premissas!$C$20+K8*Premissas!$C$21 | L20: =SUM(C20:K20)
A21: Horas totais (concurso + contratos) | B21: h | C21: =C20+C18 | D21: =D20+D18 | E21: =E20+E18 | F21: =F20+F18 | G21: =G20+G18 | H21: =H20+H18 | I21: =I20+I18 | J21: =J20+J18 | K21: =K20+K18
A22: Teto de horas | B22: h | C22: =Premissas!$C$23 | D22: =Premissas!$C$23 | E22: =Premissas!$C$23 | F22: =Premissas!$C$23 | G22: =Premissas!$C$23 | H22: =Premissas!$C$23 | I22: =Premissas!$C$23 | J22: =Premissas!$C$23 | K22: =Premissas!$C$23
A23: Capacidade | C23: =IF(C21>C22,"ESTOURA","ok") | D23: =IF(D21>D22,"ESTOURA","ok") | E23: =IF(E21>E22,"ESTOURA","ok") | F23: =IF(F21>F22,"ESTOURA","ok") | G23: =IF(G21>G22,"ESTOURA","ok") | H23: =IF(H21>H22,"ESTOURA","ok") | I23: =IF(I21>I22,"ESTOURA","ok") | J23: =IF(J21>J22,"ESTOURA","ok") | K23: =IF(K21>K22,"ESTOURA","ok")
A24: CAIXA DOS CONCURSOS
A25: + Prêmios | B25: R$ | C25: =C12+C13 | D25: =D12+D13 | E25: =E12+E13 | F25: =F12+F13 | G25: =G12+G13 | H25: =H12+H13 | I25: =I12+I13 | J25: =J12+J13 | K25: =K12+K13 | L25: =SUM(C25:K25)
A26: + Contratos (sua parte) | B26: R$ | C26: =C17 | D26: =D17 | E26: =E17 | F26: =F17 | G26: =G17 | H26: =H17 | I26: =I17 | J26: =J17 | K26: =K17 | L26: =SUM(C26:K26)
A27: − Impostos | B27: R$ | C27: =-(C25*Premissas!$C$18+C26*Premissas!$C$19) | D27: =-(D25*Premissas!$C$18+D26*Premissas!$C$19) | E27: =-(E25*Premissas!$C$18+E26*Premissas!$C$19) | F27: =-(F25*Premissas!$C$18+F26*Premissas!$C$19) | G27: =-(G25*Premissas!$C$18+G26*Premissas!$C$19) | H27: =-(H25*Premissas!$C$18+H26*Premissas!$C$19) | I27: =-(I25*Premissas!$C$18+I26*Premissas!$C$19) | J27: =-(J25*Premissas!$C$18+J26*Premissas!$C$19) | K27: =-(K25*Premissas!$C$18+K26*Premissas!$C$19) | L27: =SUM(C27:K27)
A28: − Ferramentas | B28: R$ | C28: =-3*Premissas!$C$25*Premissas!$C$26 | D28: =-3*Premissas!$C$25*Premissas!$C$26 | E28: =-3*Premissas!$C$25*Premissas!$C$26 | F28: =-3*Premissas!$C$25*Premissas!$C$26 | G28: =-3*Premissas!$C$25*Premissas!$C$26 | H28: =-3*Premissas!$C$25*Premissas!$C$26 | I28: =-3*Premissas!$C$25*Premissas!$C$26 | J28: =-3*Premissas!$C$25*Premissas!$C$26 | K28: =-3*Premissas!$C$25*Premissas!$C$26 | L28: =SUM(C28:K28)
A29: − Inscrições internacionais | B29: R$ | C29: =-C8*Premissas!$C$27 | D29: =-D8*Premissas!$C$27 | E29: =-E8*Premissas!$C$27 | F29: =-F8*Premissas!$C$27 | G29: =-G8*Premissas!$C$27 | H29: =-H8*Premissas!$C$27 | I29: =-I8*Premissas!$C$27 | J29: =-J8*Premissas!$C$27 | K29: =-K8*Premissas!$C$27 | L29: =SUM(C29:K29)
A30: − CNPJ e contabilidade | B30: R$ | C30: 0 | D30: =-3*Premissas!$C$28 | E30: =-3*Premissas!$C$28 | F30: =-3*Premissas!$C$28 | G30: =-3*Premissas!$C$28 | H30: =-3*Premissas!$C$28 | I30: =-3*Premissas!$C$28 | J30: =-3*Premissas!$C$28 | K30: =-3*Premissas!$C$28 | L30: =SUM(C30:K30)
A31: Caixa líquido dos concursos (soma) | B31: R$ | C31: =SUM(C25:C30) | D31: =SUM(D25:D30) | E31: =SUM(E25:E30) | F31: =SUM(F25:F30) | G31: =SUM(G25:G30) | H31: =SUM(H25:H30) | I31: =SUM(I25:I30) | J31: =SUM(J25:J30) | K31: =SUM(K25:K30) | L31: =SUM(C31:K31)
A32: − Valor das horas de concurso (custo de oportunidade) | B32: R$ | C32: =-C20*Premissas!$C$24 | D32: =-D20*Premissas!$C$24 | E32: =-E20*Premissas!$C$24 | F32: =-F20*Premissas!$C$24 | G32: =-G20*Premissas!$C$24 | H32: =-H20*Premissas!$C$24 | I32: =-I20*Premissas!$C$24 | J32: =-J20*Premissas!$C$24 | K32: =-K20*Premissas!$C$24 | L32: =SUM(C32:K32)
A33: Líquido depois das horas (soma) | B33: R$ | C33: =C31+C32 | D33: =D31+D32 | E33: =E31+E32 | F33: =F31+F32 | G33: =G31+G32 | H33: =H31+H32 | I33: =I31+I32 | J33: =J31+J32 | K33: =K31+K32 | L33: =SUM(C33:K33)
A34: RENDA TOTAL
A35: Perna 2 (PSCIP/PICIP, Revit, casa) | B35: R$ | C35: =3*Premissas!$C$29*(1+Premissas!$C$30)^((C5-1)/4)*(1+IF(C5>=Premissas!$C$32,Premissas!$C$31,0)) | D35: =3*Premissas!$C$29*(1+Premissas!$C$30)^((D5-1)/4)*(1+IF(D5>=Premissas!$C$32,Premissas!$C$31,0)) | E35: =3*Premissas!$C$29*(1+Premissas!$C$30)^((E5-1)/4)*(1+IF(E5>=Premissas!$C$32,Premissas!$C$31,0)) | F35: =3*Premissas!$C$29*(1+Premissas!$C$30)^((F5-1)/4)*(1+IF(F5>=Premissas!$C$32,Premissas!$C$31,0)) | G35: =3*Premissas!$C$29*(1+Premissas!$C$30)^((G5-1)/4)*(1+IF(G5>=Premissas!$C$32,Premissas!$C$31,0)) | H35: =3*Premissas!$C$29*(1+Premissas!$C$30)^((H5-1)/4)*(1+IF(H5>=Premissas!$C$32,Premissas!$C$31,0)) | I35: =3*Premissas!$C$29*(1+Premissas!$C$30)^((I5-1)/4)*(1+IF(I5>=Premissas!$C$32,Premissas!$C$31,0)) | J35: =3*Premissas!$C$29*(1+Premissas!$C$30)^((J5-1)/4)*(1+IF(J5>=Premissas!$C$32,Premissas!$C$31,0)) | K35: =3*Premissas!$C$29*(1+Premissas!$C$30)^((K5-1)/4)*(1+IF(K5>=Premissas!$C$32,Premissas!$C$31,0)) | L35: =SUM(C35:K35)
A36: Renda total do trimestre (caixa concursos + perna 2) | B36: R$ | C36: =C31+C35 | D36: =D31+D35 | E36: =E31+E35 | F36: =F31+F35 | G36: =G31+G35 | H36: =H31+H35 | I36: =I31+I35 | J36: =J31+J35 | K36: =K31+K35 | L36: =SUM(C36:K36)
A37: Renda mensal média no trimestre | B37: R$/mês | C37: =C36/3 | D37: =D36/3 | E37: =E36/3 | F37: =F36/3 | G37: =G36/3 | H37: =H36/3 | I37: =I36/3 | J37: =J36/3 | K37: =K36/3 | L37: =L36/27
A38: Renda total acumulada | B38: R$ | C38: =C36 | D38: =C38+D36 | E38: =D38+E36 | F38: =E38+F36 | G38: =F38+G36 | H38: =G38+H36 | I38: =H38+I36 | J38: =I38+J36 | K38: =J38+K36
A39: Caixa dos concursos acumulado | B39: R$ | C39: =C31 | D39: =C39+D31 | E39: =D39+E31 | F39: =E39+F31 | G39: =F39+G31 | H39: =G39+H31 | I39: =H39+I31 | J39: =I39+J31 | K39: =J39+K31
A40: CARTEIRA
A41: Contratos esperados ganhos no período (nº) | B41: nº | L41: =L14
...

Sheet Realista
A1: CENÁRIO REALISTA — valor esperado por trimestre
A2: Amarelo = inscrições por trimestre (você escolhe). O resto é fórmula ligada à aba Premissas.
A4: Item | B4: Unid. | C4: T4/26 | D4: T1/27 | E4: T2/27 | F4: T3/27 | G4: T4/27 | H4: T1/28 | I4: T2/28 | J4: T3/28 | K4: T4/28 | L4: Total
A5: Nº do trimestre | C5: 1 | D5: 2 | E5: 3 | F5: 4 | G5: 5 | H5: 6 | I5: 7 | J5: 8 | K5: 9
A6: ENTRADAS
A7: Concursos nacionais grandes inscritos | B7: nº | C7: 2 | D7: 1 | E7: 1 | F7: 1 | G7: 1 | H7: 1 | I7: 1 | J7: 1 | K7: 2 | L7: =SUM(C7:K7)
A8: Concursos internacionais inscritos | B8: nº | C8: 1 | D8: 1 | E8: 1 | F8: 1 | G8: 1 | H8: 1 | I8: 1 | J8: 1 | K8: 1 | L8: =SUM(C8:K8)
A9: RESULTADOS (saem 1 trimestre após a inscrição)
A10: Resultados nacionais | B10: nº | C10: 0 | D10: =C7 | E10: =D7 | F10: =E7 | G10: =F7 | H10: =G7 | I10: =H7 | J10: =I7 | K10: =J7 | L10: =SUM(C10:K10)
A11: Resultados internacionais | B11: nº | C11: 0 | D11: =C8 | E11: =D8 | F11: =E8 | G11: =F8 | H11: =G8 | I11: =H8 | J11: =I8 | K11: =J8 | L11: =SUM(C11:K11)
A12: Prêmios esperados — nacionais | B12: R$ | C12: =C10*(Premissas!$D$6*Premissas!$D$10+Premissas!$D$7*Premissas!$D$11) | D12: =D10*(Premissas!$D$6*Premissas!$D$10+Premissas!$D$7*Premissas!$D$11) | E12: =E10*(Premissas!$D$6*Premissas!$D$10+Premissas!$D$7*Premissas!$D$11) | F12: =F10*(Premissas!$D$6*Premissas!$D$10+Premissas!$D$7*Premissas!$D$11) | G12: =G10*(Premissas!$D$6*Premissas!$D$10+Premissas!$D$7*Premissas!$D$11) | H12: =H10*(Premissas!$D$6*Premissas!$D$10+Premissas!$D$7*Premissas!$D$11) | I12: =I10*(Premissas!$D$6*Premissas!$D$10+Premissas!$D$7*Premissas!$D$11) | J12: =J10*(Premissas!$D$6*Premissas!$D$10+Premissas!$D$7*Premissas!$D$11) | K12: =K10*(Premissas!$D$6*Premissas!$D$10+Premissas!$D$7*Premissas!$D$11) | L12: =SUM(C12:K12)
A13: Prêmios esperados — internacionais | B13: R$ | C13: =C11*(Premissas!$D$8*Premissas!$D$12+Premissas!$D$9*Premissas!$D$13)*Premissas!$D$5 | D13: =D11*(Premissas!$D$8*Premissas!$D$12+Premissas!$D$9*Premissas!$D$13)*Premissas!$D$5 | E13: =E11*(Premissas!$D$8*Premissas!$D$12+Premissas!$D$9*Premissas!$D$13)*Premissas!$D$5 | F13: =F11*(Premissas!$D$8*Premissas!$D$12+Premissas!$D$9*Premissas!$D$13)*Premissas!$D$5 | G13: =G11*(Premissas!$D$8*Premissas!$D$12+Premissas!$D$9*Premissas!$D$13)*Premissas!$D$5 | H13: =H11*(Premissas!$D$8*Premissas!$D$12+Premissas!$D$9*Premissas!$D$13)*Premissas!$D$5 | I13: =I11*(Premissas!$D$8*Premissas!$D$12+Premissas!$D$9*Premissas!$D$13)*Premissas!$D$5 | J13: =J11*(Premissas!$D$8*Premissas!$D$12+Premissas!$D$9*Premissas!$D$13)*Premissas!$D$5 | K13: =K11*(Premissas!$D$8*Premissas!$D$12+Premissas!$D$9*Premissas!$D$13)*Premissas!$D$5 | L13: =SUM(C13:K13)
A14: Contratos esperados ganhos (nº) | B14: nº | C14: =C10*Premissas!$D$6*Premissas!$D$14 | D14: =D10*Premissas!$D$6*Premissas!$D$14 | E14: =E10*Premissas!$D$6*Premissas!$D$14 | F14: =F10*Premissas!$D$6*Premissas!$D$14 | G14: =G10*Premissas!$D$6*Premissas!$D$14 | H14: =H10*Premissas!$D$6*Premissas!$D$14 | I14: =I10*Premissas!$D$6*Premissas!$D$14 | J14: =J10*Premissas!$D$6*Premissas!$D$14 | K14: =K10*Premissas!$D$6*Premissas!$D$14 | L14: =SUM(C14:K14)
A15: CONTRATOS (pagam 3 trimestres após o resultado, em 4 parcelas)
A16: Honorário bruto recebido pelo escritório | B16: R$ | C16: =Premissas!$D$15/4*0 | D16: =Premissas!$D$15/4*0 | E16: =Premissas!$D$15/4*0 | F16: =Premissas!$D$15/4*SUM(C14:C14) | G16: =Premissas!$D$15/4*SUM(C14:D14) | H16: =Premissas!$D$15/4*SUM(C14:E14) | I16: =Premissas!$D$15/4*SUM(C14:F14) | J16: =Premissas!$D$15/4*SUM(D14:G14) | K16: =Premissas!$D$15/4*SUM(E14:H14) | L16: =SUM(C16:K16)
A17: Sua parte, antes do imposto (margem × divisão) | B17: R$ | C17: =C16*Premissas!$D$16*Premissas!$D$17 | D17: =D16*Premissas!$D$16*Premissas!$D$17 | E17: =E16*Premissas!$D$16*Premissas!$D$17 | F17: =F16*Premissas!$D$16*Premissas!$D$17 | G17: =G16*Premissas!$D$16*Premissas!$D$17 | H17: =H16*Premissas!$D$16*Premissas!$D$17 | I17: =I16*Premissas!$D$16*Premissas!$D$17 | J17: =J16*Premissas!$D$16*Premissas!$D$17 | K17: =K16*Premissas!$D$16*Premissas!$D$17 | L17: =SUM(C17:K17)
A18: Horas de execução dos contratos | B18: h | C18: =Premissas!$D$22/4*0 | D18: =Premissas!$D$22/4*0 | E18: =Premissas!$D$22/4*0 | F18: =Premissas!$D$22/4*SUM(C14:C14) | G18: =Premissas!$D$22/4*SUM(C14:D14) | H18: =Premissas!$D$22/4*SUM(C14:E14) | I18: =Premissas!$D$22/4*SUM(C14:F14) | J18: =Premissas!$D$22/4*SUM(D14:G14) | K18: =Premissas!$D$22/4*SUM(E14:H14) | L18: =SUM(C18:K18)
A19: HORAS
A20: Horas de concurso | B20: h | C20: =C7*Premissas!$D$20+C8*Premissas!$D$21 | D20: =D7*Premissas!$D$20+D8*Premissas!$D$21 | E20: =E7*Premissas!$D$20+E8*Premissas!$D$21 | F20: =F7*Premissas!$D$20+F8*Premissas!$D$21 | G20: =G7*Premissas!$D$20+G8*Premissas!$D$21 | H20: =H7*Premissas!$D$20+H8*Premissas!$D$21 | I20: =I7*Premissas!$D$20+I8*Premissas!$D$21 | J20: =J7*Premissas!$D$20+J8*Premissas!$D$21 | K20: =K7*Premissas!$D$20+K8*Premissas!$D$21 | L20: =SUM(C20:K20)
A21: Horas totais (concurso + contratos) | B21: h | C21: =C20+C18 | D21: =D20+D18 | E21: =E20+E18 | F21: =F20+F18 | G21: =G20+G18 | H21: =H20+H18 | I21: =I20+I18 | J21: =J20+J18 | K21: =K20+K18
A22: Teto de horas | B22: h | C22: =Premissas!$D$23 | D22: =Premissas!$D$23 | E22: =Premissas!$D$23 | F22: =Premissas!$D$23 | G22: =Premissas!$D$23 | H22: =Premissas!$D$23 | I22: =Premissas!$D$23 | J22: =Premissas!$D$23 | K22: =Premissas!$D$23
A23: Capacidade | C23: =IF(C21>C22,"ESTOURA","ok") | D23: =IF(D21>D22,"ESTOURA","ok") | E23: =IF(E21>E22,"ESTOURA","ok") | F23: =IF(F21>F22,"ESTOURA","ok") | G23: =IF(G21>G22,"ESTOURA","ok") | H23: =IF(H21>H22,"ESTOURA","ok") | I23: =IF(I21>I22,"ESTOURA","ok") | J23: =IF(J21>J22,"ESTOURA","ok") | K23: =IF(K21>K22,"ESTOURA","ok")
A24: CAIXA DOS CONCURSOS
A25: + Prêmios | B25: R$ | C25: =C12+C13 | D25: =D12+D13 | E25: =E12+E13 | F25: =F12+F13 | G25: =G12+G13 | H25: =H12+H13 | I25: =I12+I13 | J25: =J12+J13 | K25: =K12+K13 | L25: =SUM(C25:K25)
A26: + Contratos (sua parte) | B26: R$ | C26: =C17 | D26: =D17 | E26: =E17 | F26: =F17 | G26: =G17 | H26: =H17 | I26: =I17 | J26: =J17 | K26: =K17 | L26: =SUM(C26:K26)
A27: − Impostos | B27: R$ | C27: =-(C25*Premissas!$D$18+C26*Premissas!$D$19) | D27: =-(D25*Premissas!$D$18+D26*Premissas!$D$19) | E27: =-(E25*Premissas!$D$18+E26*Premissas!$D$19) | F27: =-(F25*Premissas!$D$18+F26*Premissas!$D$19) | G27: =-(G25*Premissas!$D$18+G26*Premissas!$D$19) | H27: =-(H25*Premissas!$D$18+H26*Premissas!$D$19) | I27: =-(I25*Premissas!$D$18+I26*Premissas!$D$19) | J27: =-(J25*Premissas!$D$18+J26*Premissas!$D$19) | K27: =-(K25*Premissas!$D$18+K26*Premissas!$D$19) | L27: =SUM(C27:K27)
A28: − Ferramentas | B28: R$ | C28: =-3*Premissas!$D$25*Premissas!$D$26 | D28: =-3*Premissas!$D$25*Premissas!$D$26 | E28: =-3*Premissas!$D$25*Premissas!$D$26 | F28: =-3*Premissas!$D$25*Premissas!$D$26 | G28: =-3*Premissas!$D$25*Premissas!$D$26 | H28: =-3*Premissas!$D$25*Premissas!$D$26 | I28: =-3*Premissas!$D$25*Premissas!$D$26 | J28: =-3*Premissas!$D$25*Premissas!$D$26 | K28: =-3*Premissas!$D$25*Premissas!$D$26 | L28: =SUM(C28:K28)
A29: − Inscrições internacionais | B29: R$ | C29: =-C8*Premissas!$D$27 | D29: =-D8*Premissas!$D$27 | E29: =-E8*Premissas!$D$27 | F29: =-F8*Premissas!$D$27 | G29: =-G8*Premissas!$D$27 | H29: =-H8*Premissas!$D$27 | I29: =-I8*Premissas!$D$27 | J29: =-J8*Premissas!$D$27 | K29: =-K8*Premissas!$D$27 | L29: =SUM(C29:K29)
A30: − CNPJ e contabilidade | B30: R$ | C30: 0 | D30: =-3*Premissas!$D$28 | E30: =-3*Premissas!$D$28 | F30: =-3*Premissas!$D$28 | G30: =-3*Premissas!$D$28 | H30: =-3*Premissas!$D$28 | I30: =-3*Premissas!$D$28 | J30: =-3*Premissas!$D$28 | K30: =-3*Premissas!$D$28 | L30: =SUM(C30:K30)
A31: Caixa líquido dos concursos (soma) | B31: R$ | C31: =SUM(C25:C30) | D31: =SUM(D25:D30) | E31: =SUM(E25:E30) | F31: =SUM(F25:F30) | G31: =SUM(G25:G30) | H31: =SUM(H25:H30) | I31: =SUM(I25:I30) | J31: =SUM(J25:J30) | K31: =SUM(K25:K30) | L31: =SUM(C31:K31)
A32: − Valor das horas de concurso (custo de oportunidade) | B32: R$ | C32: =-C20*Premissas!$D$24 | D32: =-D20*Premissas!$D$24 | E32: =-E20*Premissas!$D$24 | F32: =-F20*Premissas!$D$24 | G32: =-G20*Premissas!$D$24 | H32: =-H20*Premissas!$D$24 | I32: =-I20*Premissas!$D$24 | J32: =-J20*Premissas!$D$24 | K32: =-K20*Premissas!$D$24 | L32: =SUM(C32:K32)
A33: Líquido depois das horas (soma) | B33: R$ | C33: =C31+C32 | D33: =D31+D32 | E33: =E31+E32 | F33: =F31+F32 | G33: =G31+G32 | H33: =H31+H32 | I33: =I31+I32 | J33: =J31+J32 | K33: =K31+K32 | L33: =SUM(C33:K33)
A34: RENDA TOTAL
A35: Perna 2 (PSCIP/PICIP, Revit, casa) | B35: R$ | C35: =3*Premissas!$D$29*(1+Premissas!$D$30)^((C5-1)/4)*(1+IF(C5>=Premissas!$D$32,Premissas!$D$31,0)) | D35: =3*Premissas!$D$29*(1+Premissas!$D$30)^((D5-1)/4)*(1+IF(D5>=Premissas!$D$32,Premissas!$D$31,0)) | E35: =3*Premissas!$D$29*(1+Premissas!$D$30)^((E5-1)/4)*(1+IF(E5>=Premissas!$D$32,Premissas!$D$31,0)) | F35: =3*Premissas!$D$29*(1+Premissas!$D$30)^((F5-1)/4)*(1+IF(F5>=Premissas!$D$32,Premissas!$D$31,0)) | G35: =3*Premissas!$D$29*(1+Premissas!$D$30)^((G5-1)/4)*(1+IF(G5>=Premissas!$D$32,Premissas!$D$31,0)) | H35: =3*Premissas!$D$29*(1+Premissas!$D$30)^((H5-1)/4)*(1+IF(H5>=Premissas!$D$32,Premissas!$D$31,0)) | I35: =3*Premissas!$D$29*(1+Premissas!$D$30)^((I5-1)/4)*(1+IF(I5>=Premissas!$D$32,Premissas!$D$31,0)) | J35: =3*Premissas!$D$29*(1+Premissas!$D$30)^((J5-1)/4)*(1+IF(J5>=Premissas!$D$32,Premissas!$D$31,0)) | K35: =3*Premissas!$D$29*(1+Premissas!$D$30)^((K5-1)/4)*(1+IF(K5>=Premissas!$D$32,Premissas!$D$31,0)) | L35: =SUM(C35:K35)
A36: Renda total do trimestre (caixa concursos + perna 2) | B36: R$ | C36: =C31+C35 | D36: =D31+D35 | E36: =E31+E35 | F36: =F31+F35 | G36: =G31+G35 | H36: =H31+H35 | I36: =I31+I35 | J36: =J31+J35 | K36: =K31+K35 | L36: =SUM(C36:K36)
A37: Renda mensal média no trimestre | B37: R$/mês | C37: =C36/3 | D37: =D36/3 | E37: =E36/3 | F37: =F36/3 | G37: =G36/3 | H37: =H36/3 | I37: =I36/3 | J37: =J36/3 | K37: =K36/3 | L37: =L36/27
A38: Renda total acumulada | B38: R$ | C38: =C36 | D38: =C38+D36 | E38: =D38+E36 | F38: =E38+F36 | G38: =F38+G36 | H38: =G38+H36 | I38: =H38+I36 | J38: =I38+J36 | K38: =J38+K36
A39: Caixa dos concursos acumulado | B39: R$ | C39: =C31 | D39: =C39+D31 | E39: =D39+E31 | F39: =E39+F31 | G39: =F39+G31 | H39: =G39+H31 | I39: =H39+I31 | J39: =I39+J31 | K39: =J39+K31
A40: CARTEIRA
A41: Contratos esperados ganhos no período (nº) | B41: nº | L41: =L14
...

Sheet Otimista
A1: CENÁRIO OTIMISTA — valor esperado por trimestre
A2: Amarelo = inscrições por trimestre (você escolhe). O resto é fórmula ligada à aba Premissas.
A4: Item | B4: Unid. | C4: T4/26 | D4: T1/27 | E4: T2/27 | F4: T3/27 | G4: T4/27 | H4: T1/28 | I4: T2/28 | J4: T3/28 | K4: T4/28 | L4: Total
A5: Nº do trimestre | C5: 1 | D5: 2 | E5: 3 | F5: 4 | G5: 5 | H5: 6 | I5: 7 | J5: 8 | K5: 9
A6: ENTRADAS
A7: Concursos nacionais grandes inscritos | B7: nº | C7: 2 | D7: 2 | E7: 1 | F7: 2 | G7: 1 | H7: 2 | I7: 1 | J7: 2 | K7: 1 | L7: =SUM(C7:K7)
A8: Concursos internacionais inscritos | B8: nº | C8: 1 | D8: 1 | E8: 2 | F8: 1 | G8: 1 | H8: 1 | I8: 2 | J8: 1 | K8: 1 | L8: =SUM(C8:K8)
A9: RESULTADOS (saem 1 trimestre após a inscrição)
A10: Resultados nacionais | B10: nº | C10: 0 | D10: =C7 | E10: =D7 | F10: =E7 | G10: =F7 | H10: =G7 | I10: =H7 | J10: =I7 | K10: =J7 | L10: =SUM(C10:K10)
A11: Resultados internacionais | B11: nº | C11: 0 | D11: =C8 | E11: =D8 | F11: =E8 | G11: =F8 | H11: =G8 | I11: =H8 | J11: =I8 | K11: =J8 | L11: =SUM(C11:K11)
A12: Prêmios esperados — nacionais | B12: R$ | C12: =C10*(Premissas!$E$6*Premissas!$E$10+Premissas!$E$7*Premissas!$E$11) | D12: =D10*(Premissas!$E$6*Premissas!$E$10+Premissas!$E$7*Premissas!$E$11) | E12: =E10*(Premissas!$E$6*Premissas!$E$10+Premissas!$E$7*Premissas!$E$11) | F12: =F10*(Premissas!$E$6*Premissas!$E$10+Premissas!$E$7*Premissas!$E$11) | G12: =G10*(Premissas!$E$6*Premissas!$E$10+Premissas!$E$7*Premissas!$E$11) | H12: =H10*(Premissas!$E$6*Premissas!$E$10+Premissas!$E$7*Premissas!$E$11) | I12: =I10*(Premissas!$E$6*Premissas!$E$10+Premissas!$E$7*Premissas!$E$11) | J12: =J10*(Premissas!$E$6*Premissas!$E$10+Premissas!$E$7*Premissas!$E$11) | K12: =K10*(Premissas!$E$6*Premissas!$E$10+Premissas!$E$7*Premissas!$E$11) | L12: =SUM(C12:K12)
A13: Prêmios esperados — internacionais | B13: R$ | C13: =C11*(Premissas!$E$8*Premissas!$E$12+Premissas!$E$9*Premissas!$E$13)*Premissas!$E$5 | D13: =D11*(Premissas!$E$8*Premissas!$E$12+Premissas!$E$9*Premissas!$E$13)*Premissas!$E$5 | E13: =E11*(Premissas!$E$8*Premissas!$E$12+Premissas!$E$9*Premissas!$E$13)*Premissas!$E$5 | F13: =F11*(Premissas!$E$8*Premissas!$E$12+Premissas!$E$9*Premissas!$E$13)*Premissas!$E$5 | G13: =G11*(Premissas!$E$8*Premissas!$E$12+Premissas!$E$9*Premissas!$E$13)*Premissas!$E$5 | H13: =H11*(Premissas!$E$8*Premissas!$E$12+Premissas!$E$9*Premissas!$E$13)*Premissas!$E$5 | I13: =I11*(Premissas!$E$8*Premissas!$E$12+Premissas!$E$9*Premissas!$E$13)*Premissas!$E$5 | J13: =J11*(Premissas!$E$8*Premissas!$E$12+Premissas!$E$9*Premissas!$E$13)*Premissas!$E$5 | K13: =K11*(Premissas!$E$8*Premissas!$E$12+Premissas!$E$9*Premissas!$E$13)*Premissas!$E$5 | L13: =SUM(C13:K13)
A14: Contratos esperados ganhos (nº) | B14: nº | C14: =C10*Premissas!$E$6*Premissas!$E$14 | D14: =D10*Premissas!$E$6*Premissas!$E$14 | E14: =E10*Premissas!$E$6*Premissas!$E$14 | F14: =F10*Premissas!$E$6*Premissas!$E$14 | G14: =G10*Premissas!$E$6*Premissas!$E$14 | H14: =H10*Premissas!$E$6*Premissas!$E$14 | I14: =I10*Premissas!$E$6*Premissas!$E$14 | J14: =J10*Premissas!$E$6*Premissas!$E$14 | K14: =K10*Premissas!$E$6*Premissas!$E$14 | L14: =SUM(C14:K14)
A15: CONTRATOS (pagam 3 trimestres após o resultado, em 4 parcelas)
A16: Honorário bruto recebido pelo escritório | B16: R$ | C16: =Premissas!$E$15/4*0 | D16: =Premissas!$E$15/4*0 | E16: =Premissas!$E$15/4*0 | F16: =Premissas!$E$15/4*SUM(C14:C14) | G16: =Premissas!$E$15/4*SUM(C14:D14) | H16: =Premissas!$E$15/4*SUM(C14:E14) | I16: =Premissas!$E$15/4*SUM(C14:F14) | J16: =Premissas!$E$15/4*SUM(D14:G14) | K16: =Premissas!$E$15/4*SUM(E14:H14) | L16: =SUM(C16:K16)
A17: Sua parte, antes do imposto (margem × divisão) | B17: R$ | C17: =C16*Premissas!$E$16*Premissas!$E$17 | D17: =D16*Premissas!$E$16*Premissas!$E$17 | E17: =E16*Premissas!$E$16*Premissas!$E$17 | F17: =F16*Premissas!$E$16*Premissas!$E$17 | G17: =G16*Premissas!$E$16*Premissas!$E$17 | H17: =H16*Premissas!$E$16*Premissas!$E$17 | I17: =I16*Premissas!$E$16*Premissas!$E$17 | J17: =J16*Premissas!$E$16*Premissas!$E$17 | K17: =K16*Premissas!$E$16*Premissas!$E$17 | L17: =SUM(C17:K17)
A18: Horas de execução dos contratos | B18: h | C18: =Premissas!$E$22/4*0 | D18: =Premissas!$E$22/4*0 | E18: =Premissas!$E$22/4*0 | F18: =Premissas!$E$22/4*SUM(C14:C14) | G18: =Premissas!$E$22/4*SUM(C14:D14) | H18: =Premissas!$E$22/4*SUM(C14:E14) | I18: =Premissas!$E$22/4*SUM(C14:F14) | J18: =Premissas!$E$22/4*SUM(D14:G14) | K18: =Premissas!$E$22/4*SUM(E14:H14) | L18: =SUM(C18:K18)
A19: HORAS
A20: Horas de concurso | B20: h | C20: =C7*Premissas!$E$20+C8*Premissas!$E$21 | D20: =D7*Premissas!$E$20+D8*Premissas!$E$21 | E20: =E7*Premissas!$E$20+E8*Premissas!$E$21 | F20: =F7*Premissas!$E$20+F8*Premissas!$E$21 | G20: =G7*Premissas!$E$20+G8*Premissas!$E$21 | H20: =H7*Premissas!$E$20+H8*Premissas!$E$21 | I20: =I7*Premissas!$E$20+I8*Premissas!$E$21 | J20: =J7*Premissas!$E$20+J8*Premissas!$E$21 | K20: =K7*Premissas!$E$20+K8*Premissas!$E$21 | L20: =SUM(C20:K20)
A21: Horas totais (concurso + contratos) | B21: h | C21: =C20+C18 | D21: =D20+D18 | E21: =E20+E18 | F21: =F20+F18 | G21: =G20+G18 | H21: =H20+H18 | I21: =I20+I18 | J21: =J20+J18 | K21: =K20+K18
A22: Teto de horas | B22: h | C22: =Premissas!$E$23 | D22: =Premissas!$E$23 | E22: =Premissas!$E$23 | F22: =Premissas!$E$23 | G22: =Premissas!$E$23 | H22: =Premissas!$E$23 | I22: =Premissas!$E$23 | J22: =Premissas!$E$23 | K22: =Premissas!$E$23
A23: Capacidade | C23: =IF(C21>C22,"ESTOURA","ok") | D23: =IF(D21>D22,"ESTOURA","ok") | E23: =IF(E21>E22,"ESTOURA","ok") | F23: =IF(F21>F22,"ESTOURA","ok") | G23: =IF(G21>G22,"ESTOURA","ok") | H23: =IF(H21>H22,"ESTOURA","ok") | I23: =IF(I21>I22,"ESTOURA","ok") | J23: =IF(J21>J22,"ESTOURA","ok") | K23: =IF(K21>K22,"ESTOURA","ok")
A24: CAIXA DOS CONCURSOS
A25: + Prêmios | B25: R$ | C25: =C12+C13 | D25: =D12+D13 | E25: =E12+E13 | F25: =F12+F13 | G25: =G12+G13 | H25: =H12+H13 | I25: =I12+I13 | J25: =J12+J13 | K25: =K12+K13 | L25: =SUM(C25:K25)
A26: + Contratos (sua parte) | B26: R$ | C26: =C17 | D26: =D17 | E26: =E17 | F26: =F17 | G26: =G17 | H26: =H17 | I26: =I17 | J26: =J17 | K26: =K17 | L26: =SUM(C26:K26)
A27: − Impostos | B27: R$ | C27: =-(C25*Premissas!$E$18+C26*Premissas!$E$19) | D27: =-(D25*Premissas!$E$18+D26*Premissas!$E$19) | E27: =-(E25*Premissas!$E$18+E26*Premissas!$E$19) | F27: =-(F25*Premissas!$E$18+F26*Premissas!$E$19) | G27: =-(G25*Premissas!$E$18+G26*Premissas!$E$19) | H27: =-(H25*Premissas!$E$18+H26*Premissas!$E$19) | I27: =-(I25*Premissas!$E$18+I26*Premissas!$E$19) | J27: =-(J25*Premissas!$E$18+J26*Premissas!$E$19) | K27: =-(K25*Premissas!$E$18+K26*Premissas!$E$19) | L27: =SUM(C27:K27)
A28: − Ferramentas | B28: R$ | C28: =-3*Premissas!$E$25*Premissas!$E$26 | D28: =-3*Premissas!$E$25*Premissas!$E$26 | E28: =-3*Premissas!$E$25*Premissas!$E$26 | F28: =-3*Premissas!$E$25*Premissas!$E$26 | G28: =-3*Premissas!$E$25*Premissas!$E$26 | H28: =-3*Premissas!$E$25*Premissas!$E$26 | I28: =-3*Premissas!$E$25*Premissas!$E$26 | J28: =-3*Premissas!$E$25*Premissas!$E$26 | K28: =-3*Premissas!$E$25*Premissas!$E$26 | L28: =SUM(C28:K28)
A29: − Inscrições internacionais | B29: R$ | C29: =-C8*Premissas!$E$27 | D29: =-D8*Premissas!$E$27 | E29: =-E8*Premissas!$E$27 | F29: =-F8*Premissas!$E$27 | G29: =-G8*Premissas!$E$27 | H29: =-H8*Premissas!$E$27 | I29: =-I8*Premissas!$E$27 | J29: =-J8*Premissas!$E$27 | K29: =-K8*Premissas!$E$27 | L29: =SUM(C29:K29)
A30: − CNPJ e contabilidade | B30: R$ | C30: 0 | D30: =-3*Premissas!$E$28 | E30: =-3*Premissas!$E$28 | F30: =-3*Premissas!$E$28 | G30: =-3*Premissas!$E$28 | H30: =-3*Premissas!$E$28 | I30: =-3*Premissas!$E$28 | J30: =-3*Premissas!$E$28 | K30: =-3*Premissas!$E$28 | L30: =SUM(C30:K30)
A31: Caixa líquido dos concursos (soma) | B31: R$ | C31: =SUM(C25:C30) | D31: =SUM(D25:D30) | E31: =SUM(E25:E30) | F31: =SUM(F25:F30) | G31: =SUM(G25:G30) | H31: =SUM(H25:H30) | I31: =SUM(I25:I30) | J31: =SUM(J25:J30) | K31: =SUM(K25:K30) | L31: =SUM(C31:K31)
A32: − Valor das horas de concurso (custo de oportunidade) | B32: R$ | C32: =-C20*Premissas!$E$24 | D32: =-D20*Premissas!$E$24 | E32: =-E20*Premissas!$E$24 | F32: =-F20*Premissas!$E$24 | G32: =-G20*Premissas!$E$24 | H32: =-H20*Premissas!$E$24 | I32: =-I20*Premissas!$E$24 | J32: =-J20*Premissas!$E$24 | K32: =-K20*Premissas!$E$24 | L32: =SUM(C32:K32)
A33: Líquido depois das horas (soma) | B33: R$ | C33: =C31+C32 | D33: =D31+D32 | E33: =E31+E32 | F33: =F31+F32 | G33: =G31+G32 | H33: =H31+H32 | I33: =I31+I32 | J33: =J31+J32 | K33: =K31+K32 | L33: =SUM(C33:K33)
A34: RENDA TOTAL
A35: Perna 2 (PSCIP/PICIP, Revit, casa) | B35: R$ | C35: =3*Premissas!$E$29*(1+Premissas!$E$30)^((C5-1)/4)*(1+IF(C5>=Premissas!$E$32,Premissas!$E$31,0)) | D35: =3*Premissas!$E$29*(1+Premissas!$E$30)^((D5-1)/4)*(1+IF(D5>=Premissas!$E$32,Premissas!$E$31,0)) | E35: =3*Premissas!$E$29*(1+Premissas!$E$30)^((E5-1)/4)*(1+IF(E5>=Premissas!$E$32,Premissas!$E$31,0)) | F35: =3*Premissas!$E$29*(1+Premissas!$E$30)^((F5-1)/4)*(1+IF(F5>=Premissas!$E$32,Premissas!$E$31,0)) | G35: =3*Premissas!$E$29*(1+Premissas!$E$30)^((G5-1)/4)*(1+IF(G5>=Premissas!$E$32,Premissas!$E$31,0)) | H35: =3*Premissas!$E$29*(1+Premissas!$E$30)^((H5-1)/4)*(1+IF(H5>=Premissas!$E$32,Premissas!$E$31,0)) | I35: =3*Premissas!$E$29*(1+Premissas!$E$30)^((I5-1)/4)*(1+IF(I5>=Premissas!$E$32,Premissas!$E$31,0)) | J35: =3*Premissas!$E$29*(1+Premissas!$E$30)^((J5-1)/4)*(1+IF(J5>=Premissas!$E$32,Premissas!$E$31,0)) | K35: =3*Premissas!$E$29*(1+Premissas!$E$30)^((K5-1)/4)*(1+IF(K5>=Premissas!$E$32,Premissas!$E$31,0)) | L35: =SUM(C35:K35)
A36: Renda total do trimestre (caixa concursos + perna 2) | B36: R$ | C36: =C31+C35 | D36: =D31+D35 | E36: =E31+E35 | F36: =F31+F35 | G36: =G31+G35 | H36: =H31+H35 | I36: =I31+I35 | J36: =J31+J35 | K36: =K31+K35 | L36: =SUM(C36:K36)
A37: Renda mensal média no trimestre | B37: R$/mês | C37: =C36/3 | D37: =D36/3 | E37: =E36/3 | F37: =F36/3 | G37: =G36/3 | H37: =H36/3 | I37: =I36/3 | J37: =J36/3 | K37: =K36/3 | L37: =L36/27
A38: Renda total acumulada | B38: R$ | C38: =C36 | D38: =C38+D36 | E38: =D38+E36 | F38: =E38+F36 | G38: =F38+G36 | H38: =G38+H36 | I38: =H38+I36 | J38: =I38+J36 | K38: =J38+K36
A39: Caixa dos concursos acumulado | B39: R$ | C39: =C31 | D39: =C39+D31 | E39: =D39+E31 | F39: =E39+F31 | G39: =F39+G31 | H39: =G39+H31 | I39: =H39+I31 | J39: =I39+J31 | K39: =J39+K31
A40: CARTEIRA
A41: Contratos esperados ganhos no período (nº) | B41: nº | L41: =L14
...

Sheet Monte Carlo
A1: MONTE CARLO — 20 mil rodadas por cenário (FIXO, não recalcula)
A2: Mesmas premissas da aba Premissas na data de geração. Mostra a dispersão, que o valor esperado esconde. 'Caixa' = caixa líquido dos concursos até dez/2028 (depois de imposto, ferramentas, inscrições e CNPJ), sem o valor das horas.
A4: Métrica | B4: Conservador | C4: Realista | D4: Otimista
A5: Chance de nenhum 1º lugar em todo o período | B5: 0.87515 | C5: 0.67305 | D5: 0.44495
A6: Chance de ganhar pelo menos 1 contrato | B6: 0.0402 | C6: 0.17445 | D6: 0.38915
A7: Contratos ganhos (média) | B7: 0.04095 | C7: 0.1902 | D7: 0.48255
A8: Caixa dos concursos até dez/2028 — média | B8: -44674.79 | C8: -12007.114 | D8: 65364.791
A9: Caixa dos concursos até dez/2028 — P10 (pior 10%) | B9: -58620 | C9: -53680 | D9: -40215
A10: Caixa dos concursos até dez/2028 — mediana | B10: -51820 | C10: -37870 | D10: 20985
A11: Caixa dos concursos até dez/2028 — P90 (melhor 10%) | B11: -17820 | C11: 70420 | D11: 243330
A12: Carteira de contratos a receber após 2028 — média | B12: 1312.8019 | C12: 10655.424 | D12: 50205.424
A13: Carteira a receber após 2028 — P90 | B13: 0 | C13: 56595 | D13: 194040
A14: Chance de caixa dos concursos ficar negativo até 2028 | B14: 0.95025 | C14: 0.72295 | D14: 0.4342
A17: Conferência: média do Monte Carlo vs. valor esperado do modelo (devem bater, dentro do ruído).
A18: Caixa dos concursos — média Monte Carlo | B18: -44674.79 | C18: -12007.114 | D18: 65364.791
A19: Caixa dos concursos — modelo (aba do cenário) | B19: ='Conservador'!L31 | C19: ='Realista'!L31 | D19: ='Otimista'!L31

Sheet Marcos
A1: MARCOS 2026–2028 — o que destrava o dinheiro
A2: Datas dos concursos vêm do que li antes: confira nos editais. O resto é recomendação minha.
A4: Quando | B4: Marco | C4: Por que importa | D4: Tipo
A5: 21/10/2026 | B5: Entrega UFC CACE | C5: Maior valor esperado da carteira (contrato de R$ 7,24 mi de obra). Só aceita consórcio na inscrição. | D5: Edital
A6: 30/10/2026 | B6: CAU do autor ativo (exigência do Sesc Carmo) | C6: Sem CAU ativo, o Sesc Carmo é desclassificado. | D6: Edital
A7: 11/11/2026 | B7: Entrega Museu de Maringá | C7: Exige CNPJ e acervo CAT-A do vencedor. | D7: Edital
A8: 03/12/2026 | B8: Sesc Carmo fase 1 | C8: Líquido esperado levemente negativo; decisão é sua. | D8: Edital
A9: 16/12/2026 | B9: House of Poetry | C9: Dezembro estoura o teto (200 h): tire um dos dois. | D9: Edital
A10: até dez/2026 | B10: Abrir o CNPJ da Djan Arquitetura | C10: Sem empresa, um 1º lugar pode virar só troféu. É o maior gargalo. | D10: Ação
A11: até dez/2026 | B11: Definir acervo CAT-A: seu, de sócio ou de consórcio | C11: Mesma razão: contrato público exige atestado de porte. | D11: Ação
A12: T1/2027 | B12: Resultados UFC e Maringá | C12: Primeiro teste real do método. Qualquer resultado entra no portfólio. | D12: Previsão
A13: 19/02/2027 | B13: Sassari | C13: Só vale com parceiro italiano; com Unbuilt 2027 dá 315 h em fevereiro. | D13: Edital
A14: 2027 | B14: 4 a 6 nacionais com contrato, no máximo 1 grande por vez | C14: Escalona a carga e concentra horas onde há contrato. | D14: Estratégia
A15: 2027 | B15: Cada concurso perdido vira peça de portfólio | C15: Vitrine para cliente privado e para convites. | D15: Estratégia
... A19: dez/2028 | B19: Balanço: carteira a receber, CNPJ, portfólio premiado | C19: A linha 'carteira a receber após 2028' mostra o que já está ganho e ainda não pago. | D19: Revisão
